Traceback (most recent call last):
  File "/opt/hostedtoolcache/Python/3.10.10/x64/lib/python3.10/site-packages/jupyter_cache/executors/utils.py", line 58, in single_nb_execution
    executenb(
  File "/opt/hostedtoolcache/Python/3.10.10/x64/lib/python3.10/site-packages/nbclient/client.py", line 1204, in execute
    return NotebookClient(nb=nb, resources=resources, km=km, **kwargs).execute()
  File "/opt/hostedtoolcache/Python/3.10.10/x64/lib/python3.10/site-packages/nbclient/util.py", line 84, in wrapped
    return just_run(coro(*args, **kwargs))
  File "/opt/hostedtoolcache/Python/3.10.10/x64/lib/python3.10/site-packages/nbclient/util.py", line 62, in just_run
    return loop.run_until_complete(coro)
  File "/opt/hostedtoolcache/Python/3.10.10/x64/lib/python3.10/asyncio/base_events.py", line 649, in run_until_complete
    return future.result()
  File "/opt/hostedtoolcache/Python/3.10.10/x64/lib/python3.10/site-packages/nbclient/client.py", line 663, in async_execute
    await self.async_execute_cell(
  File "/opt/hostedtoolcache/Python/3.10.10/x64/lib/python3.10/site-packages/nbclient/client.py", line 965, in async_execute_cell
    await self._check_raise_for_error(cell, cell_index, exec_reply)
  File "/opt/hostedtoolcache/Python/3.10.10/x64/lib/python3.10/site-packages/nbclient/client.py", line 862, in _check_raise_for_error
    raise CellExecutionError.from_cell_and_msg(cell, exec_reply_content)
nbclient.exceptions.CellExecutionError: An error occurred while executing the following cell:
------------------
import oemof.solph as solph


hp_thermal_power = 9.1  # kW
cop = input_data["simple TESPy COP"][:-1]

heat_pump = solph.components.Transformer(
    label="heat pump",
    inputs={bus_electricity: solph.Flow()},
    outputs={
        bus_heat_35C: solph.Flow(
            nominal_value=hp_thermal_power,
            nonconvex=solph.NonConvex(),
            min=0.5,
        )
    },
    conversion_factors={
        bus_electricity: 1 / cop,
        bus_heat_35C: 1,
    },
)

es.add(heat_pump)
------------------

[0;31m---------------------------------------------------------------------------[0m
[0;31mKeyError[0m                                  Traceback (most recent call last)
File [0;32m/opt/hostedtoolcache/Python/3.10.10/x64/lib/python3.10/site-packages/pandas/core/indexes/base.py:3802[0m, in [0;36mIndex.get_loc[0;34m(self, key, method, tolerance)[0m
[1;32m   3801[0m [38;5;28;01mtry[39;00m:
[0;32m-> 3802[0m     [38;5;28;01mreturn[39;00m [38;5;28;43mself[39;49m[38;5;241;43m.[39;49m[43m_engine[49m[38;5;241;43m.[39;49m[43mget_loc[49m[43m([49m[43mcasted_key[49m[43m)[49m
[1;32m   3803[0m [38;5;28;01mexcept[39;00m [38;5;167;01mKeyError[39;00m [38;5;28;01mas[39;00m err:

File [0;32m/opt/hostedtoolcache/Python/3.10.10/x64/lib/python3.10/site-packages/pandas/_libs/index.pyx:138[0m, in [0;36mpandas._libs.index.IndexEngine.get_loc[0;34m()[0m

File [0;32m/opt/hostedtoolcache/Python/3.10.10/x64/lib/python3.10/site-packages/pandas/_libs/index.pyx:165[0m, in [0;36mpandas._libs.index.IndexEngine.get_loc[0;34m()[0m

File [0;32mpandas/_libs/hashtable_class_helper.pxi:5745[0m, in [0;36mpandas._libs.hashtable.PyObjectHashTable.get_item[0;34m()[0m

File [0;32mpandas/_libs/hashtable_class_helper.pxi:5753[0m, in [0;36mpandas._libs.hashtable.PyObjectHashTable.get_item[0;34m()[0m

[0;31mKeyError[0m: 'simple TESPy COP'

The above exception was the direct cause of the following exception:

[0;31mKeyError[0m                                  Traceback (most recent call last)
Cell [0;32mIn[2], line 5[0m
[1;32m      1[0m [38;5;28;01mimport[39;00m [38;5;21;01moemof[39;00m[38;5;21;01m.[39;00m[38;5;21;01msolph[39;00m [38;5;28;01mas[39;00m [38;5;21;01msolph[39;00m
[1;32m      4[0m hp_thermal_power [38;5;241m=[39m [38;5;241m9.1[39m  [38;5;66;03m# kW[39;00m
[0;32m----> 5[0m cop [38;5;241m=[39m [43minput_data[49m[43m[[49m[38;5;124;43m"[39;49m[38;5;124;43msimple TESPy COP[39;49m[38;5;124;43m"[39;49m[43m][49m[:[38;5;241m-[39m[38;5;241m1[39m]
[1;32m      7[0m heat_pump [38;5;241m=[39m solph[38;5;241m.[39mcomponents[38;5;241m.[39mTransformer(
[1;32m      8[0m     label[38;5;241m=[39m[38;5;124m"[39m[38;5;124mheat pump[39m[38;5;124m"[39m,
[1;32m      9[0m     inputs[38;5;241m=[39m{bus_electricity: solph[38;5;241m.[39mFlow()},
[0;32m   (...)[0m
[1;32m     20[0m     },
[1;32m     21[0m )
[1;32m     23[0m es[38;5;241m.[39madd(heat_pump)

File [0;32m/opt/hostedtoolcache/Python/3.10.10/x64/lib/python3.10/site-packages/pandas/core/frame.py:3807[0m, in [0;36mDataFrame.__getitem__[0;34m(self, key)[0m
[1;32m   3805[0m [38;5;28;01mif[39;00m [38;5;28mself[39m[38;5;241m.[39mcolumns[38;5;241m.[39mnlevels [38;5;241m>[39m [38;5;241m1[39m:
[1;32m   3806[0m     [38;5;28;01mreturn[39;00m [38;5;28mself[39m[38;5;241m.[39m_getitem_multilevel(key)
[0;32m-> 3807[0m indexer [38;5;241m=[39m [38;5;28;43mself[39;49m[38;5;241;43m.[39;49m[43mcolumns[49m[38;5;241;43m.[39;49m[43mget_loc[49m[43m([49m[43mkey[49m[43m)[49m
[1;32m   3808[0m [38;5;28;01mif[39;00m is_integer(indexer):
[1;32m   3809[0m     indexer [38;5;241m=[39m [indexer]

File [0;32m/opt/hostedtoolcache/Python/3.10.10/x64/lib/python3.10/site-packages/pandas/core/indexes/base.py:3804[0m, in [0;36mIndex.get_loc[0;34m(self, key, method, tolerance)[0m
[1;32m   3802[0m     [38;5;28;01mreturn[39;00m [38;5;28mself[39m[38;5;241m.[39m_engine[38;5;241m.[39mget_loc(casted_key)
[1;32m   3803[0m [38;5;28;01mexcept[39;00m [38;5;167;01mKeyError[39;00m [38;5;28;01mas[39;00m err:
[0;32m-> 3804[0m     [38;5;28;01mraise[39;00m [38;5;167;01mKeyError[39;00m(key) [38;5;28;01mfrom[39;00m [38;5;21;01merr[39;00m
[1;32m   3805[0m [38;5;28;01mexcept[39;00m [38;5;167;01mTypeError[39;00m:
[1;32m   3806[0m     [38;5;66;03m# If we have a listlike key, _check_indexing_error will raise[39;00m
[1;32m   3807[0m     [38;5;66;03m#  InvalidIndexError. Otherwise we fall through and re-raise[39;00m
[1;32m   3808[0m     [38;5;66;03m#  the TypeError.[39;00m
[1;32m   3809[0m     [38;5;28mself[39m[38;5;241m.[39m_check_indexing_error(key)

[0;31mKeyError[0m: 'simple TESPy COP'
KeyError: 'simple TESPy COP'

